Workbook

Sheet Dashboard
A1: PRODUCT SALES AND PROFIT PERFORMANCE DASHBOARD
A2: B.Sc. Data Science Project | Real-time Business Metrics, Group Summaries & Visual Trends
A4: TOTAL REVENUE | C4: TOTAL COST | E4: TOTAL PROFIT | G4: PROFIT MARGIN | I4: TOTAL UNITS SOLD | K4: TOTAL ORDERS
A5: =SUM(Cleaned_Data!J2:J301) | C5: =SUM(Cleaned_Data!K2:K301) | E5: =SUM(Cleaned_Data!L2:L301) | G5: =(E5/A5) | I5: =SUM(Cleaned_Data!G2:G301) | K5: =COUNTA(Cleaned_Data!A2:A301)
A8: CATEGORY-WISE PERFORMANCE SUMMARY
A9: Category | B9: Orders | C9: Units Sold | D9: Revenue (INR) | E9: Profit (INR) | F9: Profit Margin %
A10: Electronics | B10: 86 | C10: 275 | D10: 3108427.1 | E10: 667267.13 | F10: 0.2147
A11: Furniture | B11: 95 | C11: 282 | D11: 2299235.8 | E11: 730135.76 | F11: 0.3176
A12: Accessories | B12: 59 | C12: 445 | D12: 844817.44 | E12: 367777.44 | F12: 0.4353
A13: Office Supplies | B13: 60 | C13: 434 | D13: 156733.6 | E13: 71303.6 | F13: 0.4549
A16: REGIONAL PERFORMANCE SUMMARY
A17: Region | B17: Orders | C17: Units Sold | D17: Revenue (INR) | E17: Profit (INR) | F17: Profit Margin %
A18: North | B18: 88 | C18: 431 | D18: 1962170.6 | E18: 525680.62 | F18: 0.2679
A19: South | B19: 73 | C19: 382 | D19: 1508393.7 | E19: 458583.71 | F19: 0.304
A20: West | B20: 64 | C20: 283 | D20: 1440567 | E20: 427337.01 | F20: 0.2966
A21: East | B21: 49 | C21: 211 | D21: 1089556.4 | E21: 305696.36 | F21: 0.2806
A22: Central | B22: 26 | C22: 129 | D22: 408526.23 | E22: 119186.23 | F22: 0.2917
A26: HOW TO INTERACT & ADD EXCEL PIVOTTABLES / SLICERS:
A27: 1. Interactive Slicers: Open this file in Microsoft Excel -> Go to 'Cleaned_Data' sheet -> Select any cell in the table.
A28: 2. Click 'Insert' ribbon -> Click 'PivotTable' -> Select New or Existing Worksheet.
A29: 3. Drag 'Category' or 'Region' to Rows and 'Revenue' & 'Profit' to Values.
A30: 4. Click 'Insert Slicer' in the PivotTable Analyze menu and check 'Category', 'Region', and 'Month_Name' to filter dynamically.

Sheet Raw_Data
A1: Order_ID | B1: Order_Date | C1: Product_ID | D1: Product_Name | E1: Category | F1: Region | G1: Quantity | H1: Selling_Price | I1: Cost_Price
A2: ORD-2024183 | B2: 2024-12-24 | C2: P107 | D2: Bookshelf Cabinet | E2: Furniture | F2: Central | G2: 4 | H2: 5652.5 | I2: 4100
A3: ORD-2024155 | B3: 2024-07-26 | C3: P112 | D3: USB-C Multiport Hub | E3: Accessories | F3: North | G3: 11 | H3: 1959.02 | I3: 1150
A4: ORD-2024112 | B4: 2024-10-31 | C4: P106 | D4: Standing Desk | E4: Furniture | F4: Central | G4: 4 | H4: 18130 | I4: 12500
A5: ORD-2024204 | B5: 2024-02-05 | C5: P105 | D5: Ergonomic Office Chair | E5: Furniture | F5: West | G5: 4 | H5: 9999 | I5: 6800
A6: ORD-2024061 | B6: 2024-02-11 | C6: P107 | D6: Bookshelf Cabinet | E6: Furniture | F6: East | G6: 3 | H6: 5950 | I6: 4100
A7: ORD-2024010 | B7: 2024-02-10 | C7: P109 | D7: Gel Pen Pack (10x) | E7: Office Supplies | F7: South | G7: 11 | H7: 235.2 | I7: 110
A8: ORD-2024120 | B8: 2024-02-01 | C8: P104 | D8: Noise-Cancelling Headphones | E8: Electronics | F8: West | G8: 4 | H8: 5879.02 | I8: 3600
A9: ORD-2024158 | B9: 2024-06-05 | C9: P105 | D9: Ergonomic Office Chair | E9: Furniture | F9: North | G9: 2 | H9: 9999 | I9: 6800
A10: ORD-2024168 | B10: 2024-02-07 | C10: P110 | D10: A4 Copier Paper (500s) | E10: Office Supplies | F10: East | G10: 1 | H10: 320 | I10: 190
A11: ORD-2024034 | B11: 2024-02-05 | C11: P113 | D11: Laptop Backpack | E11: Accessories | F11: East | G11: 3 | H11: 1599 | I11: 820
A12: ORD-2024006 | B12: 2024-03-22 | C12: P112 | D12: USB-C Multiport Hub | E12: Accessories | F12: South | G12: 5 | H12: 1999 | I12: 1150
A13: ORD-2024102 | B13: 2024-05-26 | C13: P104 | D13: Noise-Cancelling Headphones | E13: Electronics | F13: South | G13: 3 | H13: 5699.05 | I13: 3600
... A59: ORD-2024105 | B59: 2024-04-30 | C59: P111 | D59: Desk Organizer Tray | E59: Office Supplies | F59: South | G59: 13 | H59: 480 | I59: 260
A60: ORD-2024992 | B60: 2024-02-11 | C60: P108 | D60: Executive Desk Lamp | E60: Furniture | F60: North | H60: 1499 | I60: 850
A61: ORD-2024197 | B61: 2024-08-12 | C61: P112 | D61: USB-C Multiport Hub | E61: Accessories | F61: South | G61: 1 | H61: 1959.02 | I61: 1150
A62: ORD-2024231 | B62: 2024-05-31 | C62: P112 | D62: USB-C Multiport Hub | E62: Accessories | F62: South | G62: 14 | H62: 1899.05 | I62: 1150
A63: ORD-2024272 | B63: 2024-11-15 | C63: P111 | D63: Desk Organizer Tray | E63: Office Supplies | F63: East | G63: 12 | H63: 480 | I63: 260
A64: ORD-2024214 | B64: 2024-03-14 | C64: P107 | D64: Bookshelf Cabinet | E64: Furniture | F64: West | G64: 2 | H64: 5950 | I64: 4100
A65: ORD-2024245 | B65: 2024-10-26 | C65: P107 | D65: Bookshelf Cabinet | E65: Furniture | F65: West | G65: 3 | H65: 5950 | I65: 4100
A66: ORD-2024076 | B66: 2024-08-14 | C66: P109 | D66: Gel Pen Pack (10x) | E66: Office Supplies | F66: West | G66: 9 | H66: 240 | I66: 110
A67: ORD-2024180 | B67: 2024-08-05 | C67: P102 | D67: Wireless Mouse | E67: Electronics | F67: East | G67: 3 | H67: 750 | I67: 420
A68: ORD-2024060 | B68: 2024-10-18 | C68: P104 | D68: Noise-Cancelling Headphones | E68: Electronics | F68: East | G68: 1 | H68: 5879.02 | I68: 3600
A69: ORD-2024094 | B69: 2024-10-22 | C69: P104 | D69: Noise-Cancelling Headphones | E69: Electronics | F69: North | G69: 4 | H69: 5999 | I69: 3600
A70: ORD-2024007 | B70: 2024-04-20 | C70: P113 | D70: Laptop Backpack | E70: Accessories | F70: South | G70: 2 | H70: 1519.05 | I70: 820
A71: ORD-2024181 | B71: 2024-03-13 | C71: P102 | D71: Wireless Mouse | E71: Electronics | F71: North | G71: 5 | H71: 735 | I71: 420
A72: ORD-2024031 | B72: 2024-01-01 | C72: P110 | D72: A4 Copier Paper (500s) | E72: Office Supplies | F72: South | G72: 1 | H72: 320 | I72: 190
... A204: ORD-2024012 | B204: 2024-12-04 | C204: P104 | D204: Noise-Cancelling Headphones | E204: Electronics | F204: West | G204: 1 | H204: 5999 | I204: 3600
A205: ORD-2024991 | B205: 2024-02-05 | C205: P113 | D205: Laptop Backpack | E205: Accessories | G205: 11 | H205: 1567.02 | I205: 820
A206: ORD-2024201 | B206: 2024-09-17 | C206: P112 | D206: USB-C Multiport Hub | E206: Accessories | F206: North | G206: 14 | H206: 1899.05 | I206: 1150
A207: ORD-2024274 | B207: 2024-11-05 | C207: P107 | D207: Bookshelf Cabinet | E207: Furniture | F207: North | G207: 1 | H207: 5831 | I207: 4100
A208: ORD-2024028 | B208: 2024-05-14 | C208: P109 | D208: Gel Pen Pack (10x) | E208: Office Supplies | F208: West | G208: 9 | H208: 240 | I208: 110
A209: ORD-2024229 | B209: 2024-08-21 | C209: P114 | D209: Webcam 1080p HD | E209: Accessories | F209: South | G209: 7 | H209: 2327.5 | I209: 1450
A210: ORD-2024005 | B210: 2024-08-02 | C210: P104 | D210: Noise-Cancelling Headphones | E210: Electronics | F210: South | G210: 3 | H210: 5999 | I210: 3600
A211: ORD-2024123 | B211: 2024-10-02 | C211: P112 | D211: USB-C Multiport Hub | E211: Accessories | F211: West | G211: 13 | H211: 1959.02 | I211: 1150
A212: ORD-2024033 | B212: 2024-05-03 | C212: P110 | D212: A4 Copier Paper (500s) | E212: Office Supplies | F212: Central | G212: 2 | H212: 304 | I212: 190
A213: ORD-2024240 | B213: 2024-09-13 | C213: P105 | D213: Ergonomic Office Chair | E213: Furniture | F213: West | G213: 3 | H213: 9499.05 | I213: 6800
A214: ORD-2024163 | B214: 2024-12-28 | C214: P109 | D214: Gel Pen Pack (10x) | E214: Office Supplies | F214: North | G214: 1 | H214: 240 | I214: 110
A215: ORD-2024219 | B215: 2024-04-26 | C215: P112 | D215: USB-C Multiport Hub | E215: Accessories | F215: North | G215: 2 | H215: 1999 | I215: 1150
A216: ORD-2024262 | B216: 2024-10-03 | C216: P105 | D216: Ergonomic Office Chair | E216: Furniture | F216: West | G216: 1 | H216: 9999 | I216: 6800
...

Sheet Cleaned_Data
A1: Order_ID | B1: Order_Date | C1: Product_ID | D1: Product_Name | E1: Category | F1: Region | G1: Quantity | H1: Selling_Price | I1: Cost_Price | J1: Revenue | K1: Total_Cost | L1: Profit | M1: Profit_Margin
A2: ORD-2024031 | B2: 2024-01-01 | C2: P110 | D2: A4 Copier Paper (500s) | E2: Office Supplies | F2: South | G2: 1 | H2: 320 | I2: 190 | J2: =G2*H2 | K2: =G2*I2 | L2: =J2-K2 | M2: =(L2/J2)
A3: ORD-2024194 | B3: 2024-01-01 | C3: P111 | D3: Desk Organizer Tray | E3: Office Supplies | F3: West | G3: 8 | H3: 456 | I3: 260 | J3: =G3*H3 | K3: =G3*I3 | L3: =J3-K3 | M3: =(L3/J3)
A4: ORD-2024122 | B4: 2024-01-04 | C4: P106 | D4: Standing Desk | E4: Furniture | F4: South | G4: 4 | H4: 17575 | I4: 12500 | J4: =G4*H4 | K4: =G4*I4 | L4: =J4-K4 | M4: =(L4/J4)
A5: ORD-2024069 | B5: 2024-01-05 | C5: P111 | D5: Desk Organizer Tray | E5: Office Supplies | F5: West | G5: 5 | H5: 480 | I5: 260 | J5: =G5*H5 | K5: =G5*I5 | L5: =J5-K5 | M5: =(L5/J5)
A6: ORD-2024258 | B6: 2024-01-11 | C6: P101 | D6: Laptop Pro 15 | E6: Electronics | F6: West | G6: 2 | H6: 55000 | I6: 45000 | J6: =G6*H6 | K6: =G6*I6 | L6: =J6-K6 | M6: =(L6/J6)
A7: ORD-2024088 | B7: 2024-01-13 | C7: P111 | D7: Desk Organizer Tray | E7: Office Supplies | F7: North | G7: 6 | H7: 480 | I7: 260 | J7: =G7*H7 | K7: =G7*I7 | L7: =J7-K7 | M7: =(L7/J7)
A8: ORD-2024125 | B8: 2024-01-15 | C8: P107 | D8: Bookshelf Cabinet | E8: Furniture | F8: South | G8: 4 | H8: 5950 | I8: 4100 | J8: =G8*H8 | K8: =G8*I8 | L8: =J8-K8 | M8: =(L8/J8)
A9: ORD-2024091 | B9: 2024-01-15 | C9: P102 | D9: Wireless Mouse | E9: Electronics | F9: West | G9: 5 | H9: 750 | I9: 420 | J9: =G9*H9 | K9: =G9*I9 | L9: =J9-K9 | M9: =(L9/J9)
A10: ORD-2024149 | B10: 2024-01-15 | C10: P108 | D10: Executive Desk Lamp | E10: Furniture | F10: West | G10: 3 | H10: 1424.05 | I10: 850 | J10: =G10*H10 | K10: =G10*I10 | L10: =J10-K10 | M10: =(L10/J10)
A11: ORD-2024133 | B11: 2024-01-16 | C11: P104 | D11: Noise-Cancelling Headphones | E11: Electronics | F11: North | G11: 1 | H11: 5879.02 | I11: 3600 | J11: =G11*H11 | K11: =G11*I11 | L11: =J11-K11 | M11: =(L11/J11)
A12: ORD-2024237 | B12: 2024-01-18 | C12: P110 | D12: A4 Copier Paper (500s) | E12: Office Supplies | F12: South | G12: 3 | H12: 320 | I12: 190 | J12: =G12*H12 | K12: =G12*I12 | L12: =J12-K12 | M12: =(L12/J12)
A13: ORD-2024212 | B13: 2024-01-19 | C13: P103 | D13: Mechanical Keyboard | E13: Electronics | F13: South | G13: 3 | H13: 2800 | I13: 1850 | J13: =G13*H13 | K13: =G13*I13 | L13: =J13-K13 | M13: =(L13/J13)
... A301: ORD-2024163 | B301: 2024-12-28 | C301: P109 | D301: Gel Pen Pack (10x) | E301: Office Supplies | F301: North | G301: 1 | H301: 240 | I301: 110 | J301: =G301*H301 | K301: =G301*I301 | L301: =J301-K301 | M301: =(L301/J301)

Sheet Product_Analysis
A1: Product ID | B1: Product Name | C1: Category | D1: Orders | E1: Quantity Sold | F1: Revenue | G1: Total Cost | H1: Profit | I1: Profit Margin
A2: P101 | B2: Laptop Pro 15 | C2: Electronics | D2: 20 | E2: 45 | F2: 2430450 | G2: 2025000 | H2: 405450 | I2: 0.1668
A3: P106 | B3: Standing Desk | C3: Furniture | D3: 18 | E3: 58 | F3: 1059310 | G3: 725000 | H3: 334310 | I3: 0.3156
A4: P105 | B4: Ergonomic Office Chair | C4: Furniture | D4: 32 | E4: 76 | F4: 751424.85 | G4: 516800 | H4: 234624.85 | I4: 0.3122
A5: P104 | B5: Noise-Cancelling Headphones | C5: Electronics | D5: 33 | E5: 87 | F5: 512134.63 | G5: 313200 | H5: 198934.63 | I5: 0.3884
A6: P113 | B6: Laptop Backpack | C6: Accessories | D6: 27 | E6: 197 | F6: 310797.63 | G6: 161540 | H6: 149257.63 | I6: 0.4802
A7: P112 | B7: USB-C Multiport Hub | C7: Accessories | D7: 17 | E7: 147 | F7: 288235.81 | G7: 169050 | H7: 119185.81 | I7: 0.4135
A8: P107 | B8: Bookshelf Cabinet | C8: Furniture | D8: 25 | E8: 62 | F8: 361700.5 | G8: 254200 | H8: 107500.5 | I8: 0.2972
A9: P114 | B9: Webcam 1080p HD | C9: Accessories | D9: 15 | E9: 101 | F9: 245784 | G9: 146450 | H9: 99334 | I9: 0.4042
A10: P108 | B10: Executive Desk Lamp | C10: Furniture | D10: 20 | E10: 86 | F10: 126800.41 | G10: 73100 | H10: 53700.41 | I10: 0.4235
A11: P111 | B11: Desk Organizer Tray | C11: Office Supplies | D11: 22 | E11: 191 | F11: 89870.4 | G11: 49660 | H11: 40210.4 | I11: 0.4474
A12: P102 | B12: Wireless Mouse | C12: Electronics | D12: 22 | E12: 113 | F12: 83242.5 | G12: 47460 | H12: 35782.5 | I12: 0.4299
A13: P103 | B13: Mechanical Keyboard | C13: Electronics | D13: 11 | E13: 30 | F13: 82600 | G13: 55500 | H13: 27100 | I13: 0.3281
... A15: P110 | B15: A4 Copier Paper (500s) | C15: Office Supplies | D15: 21 | E15: 113 | F15: 35948.8 | G15: 21470 | H15: 14478.8 | I15: 0.4028

Sheet Category_Analysis
A1: Category | B1: Orders | C1: Units Sold | D1: Revenue (INR) | E1: Profit (INR) | F1: Profit Margin %
A2: Electronics | B2: 86 | C2: 275 | D2: 3108427.1 | E2: 2441160 | F2: 667267.13 | G2: 0.2147
A3: Furniture | B3: 95 | C3: 282 | D3: 2299235.8 | E3: 1569100 | F3: 730135.76 | G3: 0.3176
A4: Accessories | B4: 59 | C4: 445 | D4: 844817.44 | E4: 477040 | F4: 367777.44 | G4: 0.4353
A5: Office Supplies | B5: 60 | C5: 434 | D5: 156733.6 | E5: 85430 | F5: 71303.6 | G5: 0.4549

Sheet Monthly_Analysis
A1: Year-Month | B1: Month | C1: Orders | D1: Units Sold | E1: Revenue | F1: Total Cost | G1: Profit | H1: Profit Margin
A2: 2024-01 | B2: Jan | C2: 21 | D2: 92 | E2: 726906.68 | F2: 550000 | G2: 176906.68 | H2: 0.2434
A3: 2024-02 | B3: Feb | C3: 30 | D3: 131 | E3: 490139.86 | F3: 326770 | G3: 163369.86 | H3: 0.3333
A4: 2024-03 | B4: Mar | C4: 24 | D4: 120 | E4: 605557.56 | F4: 443910 | G4: 161647.56 | H4: 0.2669
A5: 2024-04 | B5: Apr | C5: 21 | D5: 120 | E5: 267354.66 | F5: 179840 | G5: 87514.66 | H5: 0.3273
A6: 2024-05 | B6: May | C6: 24 | D6: 125 | E6: 341937.59 | F6: 222910 | G6: 119027.59 | H6: 0.3481
A7: 2024-06 | B7: Jun | C7: 17 | D7: 67 | E7: 289291.05 | F7: 214810 | G7: 74481.05 | H7: 0.2575
A8: 2024-07 | B8: Jul | C8: 23 | D8: 100 | E8: 684667.73 | F8: 495400 | G8: 189267.73 | H8: 0.2764
A9: 2024-08 | B9: Aug | C9: 35 | D9: 166 | E9: 521126.96 | F9: 346470 | G9: 174656.96 | H9: 0.3352
A10: 2024-09 | B10: Sep | C10: 24 | D10: 114 | E10: 300844.35 | F10: 191540 | G10: 109304.35 | H10: 0.3633
A11: 2024-10 | B11: Oct | C11: 30 | D11: 125 | E11: 1125051.8 | F11: 829690 | G11: 295361.77 | H11: 0.2625
A12: 2024-11 | B12: Nov | C12: 22 | D12: 141 | E12: 464508.56 | F12: 344540 | G12: 119968.56 | H12: 0.2583
A13: 2024-12 | B13: Dec | C13: 29 | D13: 135 | E13: 591827.16 | F13: 426850 | G13: 164977.16 | H13: 0.2788

Sheet Region_Analysis
A1: Region | B1: Orders | C1: Units Sold | D1: Revenue (INR) | E1: Profit (INR) | F1: Profit Margin %
A2: North | B2: 88 | C2: 431 | D2: 1962170.6 | E2: 1436490 | F2: 525680.62 | G2: 0.2679
A3: South | B3: 73 | C3: 382 | D3: 1508393.7 | E3: 1049810 | F3: 458583.71 | G3: 0.304
A4: West | B4: 64 | C4: 283 | D4: 1440567 | E4: 1013230 | F4: 427337.01 | G4: 0.2966
A5: East | B5: 49 | C5: 211 | D5: 1089556.4 | E5: 783860 | F5: 305696.36 | G5: 0.2806
A6: Central | B6: 26 | C6: 129 | D6: 408526.23 | E6: 289340 | F6: 119186.23 | G6: 0.2917
